Workbook

Sheet BS ITC
A1: Balance Sheet of ITC (in Rs. Cr.) | B1: 45717 | C1: 45352 | D1: 44986 | E1: 44621 | F1: 44256
A2: EQUITIES AND LIABILITIES
A3: SHAREHOLDER'S FUNDS
A4: Equity Share Capital | B4: 1251.41 | C4: 1248.47 | D4: 1242.8 | E4: 1232.33 | F4: 1230.88
A5: Total Share Capital | B5: 1251.41 | C5: 1248.47 | D5: 1242.8 | E5: 1232.33 | F5: 1230.88
A6: Reserves and Surplus | B6: 68778.64 | C6: 72750.94 | D6: 67171.01 | E6: 59906.91 | F6: 57409.94
A7: Total Reserves and Surplus | B7: 68778.64 | C7: 72750.94 | D7: 67171.01 | E7: 59906.91 | F7: 57409.94
A8: Total Shareholders Funds | B8: 70030.05 | C8: 74507 | D8: 69155.26 | E8: 62455.57 | F8: 60347.34
A9: Minority Interest | B9: 367.89 | C9: 382.97 | D9: 383.53 | E9: 366.3 | F9: 346.81
A10: NON-CURRENT LIABILITIES
A11: Long Term Borrowings | B11: 0 | C11: 1.76 | D11: 3.49 | E11: 4.85 | F11: 5.58
A12: Deferred Tax Liabilities [Net] | B12: 2582.46 | C12: 2141.44 | D12: 1629 | E12: 1673.47 | F12: 1736.39
A13: Other Long Term Liabilities | B13: 473.06 | C13: 814.29 | D13: 713.08 | E13: 374.6 | F13: 506
A14: Long Term Provisions | B14: 303.11 | C14: 288.3 | D14: 259.21 | E14: 221.05 | F14: 187.5
A15: Total Non-Current Liabilities | B15: 3358.63 | C15: 3245.79 | D15: 2604.78 | E15: 2273.97 | F15: 2435.47
A16: CURRENT LIABILITIES
A17: Short Term Borrowings | B17: 91.26 | C17: 9.52 | D17: 35.32 | E17: 0.74 | F17: 3.88
A18: Trade Payables | B18: 4807.3 | C18: 4797.83 | D18: 4658.99 | E18: 4417.26 | F18: 4318.73
A19: Other Current Liabilities | B19: 9355.49 | C19: 8776.14 | D19: 8944.54 | E19: 7666.15 | F19: 6173.06
A20: Short Term Provisions | B20: 80.06 | C20: 106.91 | D20: 100.56 | E20: 79.56 | F20: 194.01
A21: Total Current Liabilities | B21: 14334.11 | C21: 13690.4 | D21: 13739.41 | E21: 12163.71 | F21: 10689.68
A22: Total Capital And Liabilities | B22: 88090.68 | C22: 91826.16 | D22: 85882.98 | E22: 77259.55 | F22: 73819.3
A23: ASSETS
A24: NON-CURRENT ASSETS
A25: Tangible Assets | B25: 18333.18 | C25: 24362.38 | D25: 22344.22 | E25: 21438.76 | F25: 20507.69
A26: Intangible Assets | B26: 2724.74 | C26: 2678.11 | D26: 2727.32 | E26: 2013.1 | F26: 2011.06
A27: Capital Work-In-Progress | B27: 1087.6 | C27: 2851.14 | D27: 2984.71 | E27: 3198.45 | F27: 4004.45
A28: Fixed Assets | B28: 22148.83 | C28: 29901.27 | D28: 28074.84 | E28: 26677.4 | F28: 26530.04
A29: Non-Current Investments | B29: 18432.32 | C29: 18169.6 | D29: 12182.16 | E29: 12576.73 | F29: 10024.54
A30: Deferred Tax Assets [Net] | B30: 87.98 | C30: 72.19 | D30: 52.02 | E30: 63.53 | F30: 58.54
A31: Long Term Loans And Advances | B31: 7.6 | C31: 4.05 | D31: 5.48 | E31: 6.61 | F31: 4.07
A32: Other Non-Current Assets | B32: 2623.74 | C32: 1833.78 | D32: 5117.86 | E32: 2923.1 | F32: 1430.39
A33: Total Non-Current Assets | B33: 44197.4 | C33: 50760.62 | D33: 46212.09 | E33: 43027.1 | F33: 38827.31
A34: CURRENT ASSETS
A35: Current Investments | B35: 16287.5 | C35: 12944.42 | D35: 17232.86 | E35: 12264.28 | F35: 14846.33
A36: Inventories | B36: 15836.14 | C36: 14302.88 | D36: 11914.13 | E36: 10973.59 | F36: 10507.22
A37: Trade Receivables | B37: 4719.67 | C37: 4025.82 | D37: 2956.17 | E37: 2461.9 | F37: 2501.7
A38: Cash And Cash Equivalents | B38: 4012.36 | C38: 7217.68 | D38: 4880.19 | E38: 4654.42 | F38: 4659.02
A39: Short Term Loans And Advances | B39: 9.51 | C39: 9.81 | D39: 7.12 | E39: 6.77 | F39: 3.47
A40: OtherCurrentAssets | B40: 3028.1 | C40: 2564.93 | D40: 2680.42 | E40: 3871.49 | F40: 2474.25
...

Sheet P&L ITC
A1: Profit & Loss account of ITC (in Rs. Cr.) | B1: 45717 | C1: 45352 | D1: 44986 | E1: 44621 | F1: 44256
A2: INCOME
A3: Revenue From Operations [Gross] | B3: 80942.76 | C3: 76274.98 | D3: 75826.58 | E3: 64618.23 | F3: 52835.15
A4: Less: Excise/Sevice Tax/Other Levies | B4: 6289.44 | C4: 5959.49 | D4: 5581.36 | E4: 4536.87 | F4: 3882.34
A5: Revenue From Operations [Net] | B5: 74653.32 | C5: 70315.49 | D5: 70245.22 | E5: 60081.36 | F5: 48952.81
A6: Total Operating Revenues | B6: 75323.34 | C6: 70881 | D6: 70936.85 | E6: 60668.09 | F6: 49272.78
A7: Other Income | B7: 2529.69 | C7: 2727.84 | D7: 1980.49 | E7: 1836.35 | F7: 2632.56
A8: Total Revenue | B8: 77853.03 | C8: 73608.84 | D8: 72917.34 | E8: 62504.44 | F8: 51905.34
A9: EXPENSES
A10: Cost Of Materials Consumed | B10: 23757.33 | C10: 21772.58 | D10: 20275.99 | E10: 16399.94 | F10: 13939.84
A11: Purchase Of Stock-In Trade | B11: 8947.04 | C11: 6063.32 | D11: 9088.37 | E11: 10671.13 | F11: 6836.87
A12: Operating And Direct Expenses | B12: 0 | C12: 0 | D12: 0 | E12: 0 | F12: 0
A13: Changes In Inventories Of FGWIP And Stock In Trade | B13: -725.65 | C13: -588.69 | D13: -358.59 | E13: -686 | F13: -645.27
A14: Employee Benefit Expenses | B14: 6169.78 | C14: 6134.35 | D14: 5736.22 | E14: 4890.55 | F14: 4463.33
A15: Finance Costs | B15: 45.06 | C15: 45.96 | D15: 43.2 | E15: 39.36 | F15: 44.58
A16: Depreciation And Amortisation Expenses | B16: 1646.32 | C16: 1816.39 | D16: 1809.01 | E16: 1732.41 | F16: 1645.59
A17: Other Expenses | B17: 11196.63 | C17: 11245.09 | D17: 10529.93 | E17: 8734.06 | F17: 7675.31
A18: Total Expenses | B18: 51036.51 | C18: 46489 | D18: 47124.13 | E18: 41781.45 | F18: 33960.25
A19: Profit/Loss Before Exceptional, ExtraOrdinary Items And Tax | B19: 26816.52 | C19: 27119.84 | D19: 25793.21 | E19: 20722.99 | F19: 17945.09
A20: Exceptional Items | B20: 0 | C20: -7.57 | D20: 72.87 | E20: 0 | F20: 0
A21: Profit/Loss Before Tax | B21: 26816.52 | C21: 27112.27 | D21: 25866.08 | E21: 20722.99 | F21: 17945.09
A22: Tax Expenses-Continued Operations
A23: Current Tax | B23: 6509.61 | C23: 6165.27 | D23: 6450.9 | E23: 5306.58 | F23: 4463.74
A24: Less: MAT Credit Entitlement | B24: 0 | C24: 0 | D24: 0 | E24: 0 | F24: 0
A25: Deferred Tax | B25: 380.86 | C25: 223.25 | D25: -12.5 | E25: -69.24 | F25: 91.55
A26: Other Direct Taxes | B26: 0 | C26: 0 | D26: 0 | E26: 0 | F26: 0
A27: Total Tax Expenses | B27: 6890.47 | C27: 6388.52 | D27: 6438.4 | E27: 5237.34 | F27: 4555.29
A28: Profit/Loss After Tax And Before ExtraOrdinary Items | B28: 19926.05 | C28: 20723.75 | D28: 19427.68 | E28: 15485.65 | F28: 13389.8
A29: Profit/Loss From Continuing Operations | B29: 19926.05 | C29: 20723.75 | D29: 19427.68 | E29: 15485.65 | F29: 13389.8
A30: Profit/Loss For The Period | B30: 34942.06 | C30: 20723.75 | D30: 19427.68 | E30: 15485.65 | F30: 13389.8
A31: Minority Interest | B31: -305.85 | C31: -292.58 | D31: -285.06 | E31: -260.47 | F31: -221.69
A32: Consolidated Profit/Loss After MI And Associates | B32: 34746.63 | C32: 20458.78 | D32: 19191.66 | E32: 15242.66 | F32: 13161.19
A33: OTHER ADDITIONAL INFORMATION
A34: EARNINGS PER SHARE
A35: Basic EPS (Rs.) | B35: 28 | C35: 16 | D35: 16 | E35: 12 | F35: 11
A36: Diluted EPS (Rs.) | B36: 28 | C36: 16 | D36: 15 | E36: 12 | F36: 11
A37: DIVIDEND AND DIVIDEND PERCENTAGE
A38: Equity Share Dividend | B38: 8133.11 | C38: 8388.91 | D38: 7448.41 | E38: 6469.48 | F38: 6152.68
A39: Tax On Dividend | B39: -19.45 | C39: 0 | D39: 0 | E39: 0 | F39: 0

Sheet BS  HUL
A1: Balance Sheet of Hindustan Unilever (in Rs. Cr.) | B1: 45717 | C1: 45352 | D1: 44986 | E1: 44621 | F1: 44256
A2: EQUITIES AND LIABILITIES
A3: SHAREHOLDER'S FUNDS
A4: Equity Share Capital | B4: 235 | C4: 235 | D4: 235 | E4: 235 | F4: 235
A5: Total Share Capital | B5: 235 | C5: 235 | D5: 235 | E5: 235 | F5: 235
A6: Reserves and Surplus | B6: 48918 | C6: 50738 | D6: 49986 | E6: 48525 | F6: 47199
A7: Total Reserves and Surplus | B7: 48918 | C7: 50738 | D7: 49986 | E7: 48525 | F7: 47199
A8: Total Shareholders Funds | B8: 49153 | C8: 50973 | D8: 50221 | E8: 48760 | F8: 47434
A9: NON-CURRENT LIABILITIES
A10: Long Term Borrowings | B10: 0 | C10: 0 | D10: 0 | E10: 0 | F10: 0
A11: Deferred Tax Liabilities [Net] | B11: 6583 | C11: 6454 | D11: 6325 | E11: 6141 | F11: 5986
A12: Other Long Term Liabilities | B12: 5396 | C12: 5695 | D12: 2317 | E12: 2339 | F12: 2304
A13: Long Term Provisions | B13: 1509 | C13: 1551 | D13: 1335 | E13: 1553 | F13: 1551
A14: Total Non-Current Liabilities | B14: 13488 | C14: 13700 | D14: 9977 | E14: 10033 | F14: 9841
A15: CURRENT LIABILITIES
A16: Short Term Borrowings | B16: 0 | C16: 0 | D16: 0 | E16: 0 | F16: 0
A17: Trade Payables | B17: 10998 | C17: 10148 | D17: 9391 | E17: 8864 | F17: 8627
A18: Other Current Liabilities | B18: 4013 | C18: 1926 | D18: 1857 | E18: 1746 | F18: 1723
A19: Short Term Provisions | B19: 661 | C19: 329 | D19: 379 | E19: 334 | F19: 491
A20: Total Current Liabilities | B20: 15672 | C20: 12403 | D20: 11627 | E20: 10944 | F20: 10841
A21: Total Capital And Liabilities | B21: 78313 | C21: 77076 | D21: 71825 | E21: 69737 | F21: 68116
A22: ASSETS
A23: NON-CURRENT ASSETS
A24: Tangible Assets | B24: 7710 | C24: 7178 | D24: 6189 | E24: 5813 | F24: 5786
A25: Intangible Assets | B25: 45197 | C25: 45201 | D25: 45216 | E25: 45221 | F25: 45241
A26: Capital Work-In-Progress | B26: 956 | C26: 915 | D26: 1020 | E26: 901 | F26: 623
A27: Other Assets | B27: 0 | C27: 0 | D27: 0 | E27: 0 | F27: 0
A28: Fixed Assets | B28: 53863 | C28: 53294 | D28: 52425 | E28: 51935 | F28: 51650
A29: Non-Current Investments | B29: 988 | C29: 983 | D29: 983 | E29: 612 | F29: 312
A30: Deferred Tax Assets [Net] | B30: 0 | C30: 0 | D30: 0 | E30: 0 | F30: 0
A31: Long Term Loans And Advances | B31: 332 | C31: 392 | D31: 339 | E31: 541 | F31: 520
A32: Other Non-Current Assets | B32: 2231 | C32: 2111 | D32: 2029 | E32: 2002 | F32: 1994
A33: Total Non-Current Assets | B33: 57414 | C33: 56780 | D33: 55776 | E33: 55090 | F33: 54476
A34: CURRENT ASSETS
A35: Current Investments | B35: 3614 | C35: 4510 | D35: 2811 | E35: 3510 | F35: 2683
A36: Inventories | B36: 4161 | C36: 3812 | D36: 4031 | E36: 3890 | F36: 3383
A37: Trade Receivables | B37: 3450 | C37: 2690 | D37: 2735 | E37: 1932 | F37: 1648
A38: Cash And Cash Equivalents | B38: 7293 | C38: 7216 | D38: 4422 | E38: 3618 | F38: 4321
A39: Short Term Loans And Advances | B39: 45 | C39: 37 | D39: 35 | E39: 34 | F39: 0
A40: OtherCurrentAssets | B40: 2336 | C40: 2031 | D40: 2015 | E40: 1663 | F40: 1605
...

Sheet P&L HUL
A1: Profit & Loss account of Hindustan Unilever (in Rs. Cr.) | B1: 45717 | C1: 45352 | D1: 44986 | E1: 44621 | F1: 44256
A2: INCOME
A3: Revenue From Operations [Gross] | B3: 62288 | C3: 60966 | D3: 59549 | E3: 51548 | F3: 46321
A4: Less: Excise/Sevice Tax/Other Levies | B4: 0 | C4: 0 | D4: 0 | E4: 0 | F4: 0
A5: Revenue From Operations [Net] | B5: 62288 | C5: 60966 | D5: 59549 | E5: 51548 | F5: 46321
A6: Total Operating Revenues | B6: 63121 | C6: 61896 | D6: 60580 | E6: 52446 | F6: 47028
A7: Other Income | B7: 1017 | C7: 811 | D7: 512 | E7: 258 | F7: 410
A8: Total Revenue | B8: 64138 | C8: 62707 | D8: 61092 | E8: 52704 | F8: 47438
A9: EXPENSES
A10: Cost Of Materials Consumed | B10: 19458 | C10: 19257 | D10: 20212 | E10: 16446 | F10: 15432
A11: Purchase Of Stock-In Trade | B11: 11273 | C11: 10514 | D11: 11579 | E11: 9311 | F11: 7121
A12: Operating And Direct Expenses | B12: 0 | C12: 0 | D12: 0 | E12: 0 | F12: 0
A13: Changes In Inventories Of FGWIP And Stock In Trade | B13: -153 | C13: -11 | D13: -75 | E13: -22 | F13: -405
A14: Employee Benefit Expenses | B14: 3077 | C14: 3009 | D14: 2854 | E14: 2545 | F14: 2358
A15: Finance Costs | B15: 395 | C15: 334 | D15: 114 | E15: 106 | F15: 117
A16: Depreciation And Amortisation Expenses | B16: 1355 | C16: 1216 | D16: 1137 | E16: 1091 | F16: 1074
A17: Other Expenses | B17: 14615 | C17: 14464 | D17: 11861 | E17: 11309 | F17: 10896
A18: Total Expenses | B18: 50020 | C18: 48783 | D18: 47682 | E18: 40786 | F18: 36593
A19: Profit/Loss Before Exceptional, ExtraOrdinary Items And Tax | B19: 14118 | C19: 13924 | D19: 13410 | E19: 11918 | F19: 10845
A20: Exceptional Items | B20: 305 | C20: 6 | D20: -64 | E20: -44 | F20: -239
A21: Profit/Loss Before Tax | B21: 14423 | C21: 13930 | D21: 13346 | E21: 11874 | F21: 10606
A22: Tax Expenses-Continued Operations
A23: Current Tax | B23: 3620 | C23: 3521 | D23: 3001 | E23: 2840 | F23: 2520
A24: Less: MAT Credit Entitlement | B24: 0 | C24: 0 | D24: 0 | E24: 0 | F24: 0
A25: Deferred Tax | B25: 124 | C25: 123 | D25: 200 | E25: 147 | F25: 86
A26: Other Direct Taxes | B26: 0 | C26: 0 | D26: 0 | E26: 0 | F26: 0
A27: Total Tax Expenses | B27: 3744 | C27: 3644 | D27: 3201 | E27: 2987 | F27: 2606
A28: Profit/Loss After Tax And Before ExtraOrdinary Items | B28: 10679 | C28: 10286 | D28: 10145 | E28: 8887 | F28: 8000
A29: Profit/Loss From Continuing Operations | B29: 10679 | C29: 10286 | D29: 10145 | E29: 8887 | F29: 8000
A30: Profit/Loss For The Period | B30: 10679 | C30: 10286 | D30: 10144 | E30: 8892 | F30: 7999
A31: Minority Interest | B31: -22 | C31: -5 | D31: -23 | E31: -13 | F31: -4
A32: Consolidated Profit/Loss After MI And Associates | B32: 10649 | C32: 10277 | D32: 10120 | E32: 8879 | F32: 7995
A33: OTHER ADDITIONAL INFORMATION
A34: EARNINGS PER SHARE
A35: Basic EPS (Rs.) | B35: 45 | C35: 44 | D35: 43 | E35: 38 | F35: 34
A36: Diluted EPS (Rs.) | B36: 45 | C36: 44 | D36: 43 | E36: 38 | F36: 34
A37: DIVIDEND AND DIVIDEND PERCENTAGE
A38: Equity Share Dividend | B38: 12453 | C38: 9398 | D38: 8459 | E38: 7519 | F38: 8811
A39: Tax On Dividend | B39: 0 | C39: 0 | D39: 0 | E39: 0 | F39: 0

Sheet BS DABUR IND
A1: Balance Sheet of Dabur India (in Rs. Cr.) | B1: 45717 | C1: 45352 | D1: 44986 | E1: 44621 | F1: 44256
A2: EQUITIES AND LIABILITIES
A3: SHAREHOLDER'S FUNDS
A4: Equity Share Capital | B4: 177.23 | C4: 177.2 | D4: 177.18 | E4: 176.79 | F4: 176.74
A5: Total Share Capital | B5: 177.23 | C5: 177.2 | D5: 177.18 | E5: 176.79 | F5: 176.74
A6: Reserves and Surplus | B6: 10623.46 | C6: 9689.1 | D6: 8737 | E6: 8056.3 | F6: 7486.79
A7: Total Reserves and Surplus | B7: 10623.46 | C7: 9689.1 | D7: 8737 | E7: 8056.3 | F7: 7486.79
A8: Total Shareholders Funds | B8: 10800.69 | C8: 9866.3 | D8: 8973.26 | E8: 8381.3 | F8: 7663.53
A9: Minority Interest | B9: 409.57 | C9: 436.78 | D9: 468.17 | E9: 40.55 | F9: 36.69
A10: NON-CURRENT LIABILITIES
A11: Long Term Borrowings | B11: 304.03 | C11: 535.97 | D11: 298.84 | E11: 250.36 | F11: 134.13
A12: Deferred Tax Liabilities [Net] | B12: 144.27 | C12: 109.03 | D12: 90.99 | E12: 82.27 | F12: 13.91
A13: Other Long Term Liabilities | B13: 183.83 | C13: 175.86 | D13: 149.31 | E13: 143.83 | F13: 1.37
A14: Long Term Provisions | B14: 71.45 | C14: 68.31 | D14: 64.37 | E14: 63.68 | F14: 63.31
A15: Total Non-Current Liabilities | B15: 703.58 | C15: 889.17 | D15: 603.51 | E15: 540.14 | F15: 212.72
A16: CURRENT LIABILITIES
A17: Short Term Borrowings | B17: 426.09 | C17: 622.1 | D17: 700.18 | E17: 617.29 | F17: 349.14
A18: Trade Payables | B18: 2825.34 | C18: 2421.71 | D18: 2186.61 | E18: 2017.95 | F18: 1915.26
A19: Other Current Liabilities | B19: 806.48 | C19: 636.73 | D19: 508.63 | E19: 501.3 | F19: 481.95
A20: Short Term Provisions | B20: 260.53 | C20: 249.89 | D20: 214.01 | E20: 186 | F20: 187.84
A21: Total Current Liabilities | B21: 4318.44 | C21: 3930.43 | D21: 3609.43 | E21: 3322.54 | F21: 2934.19
A22: Total Capital And Liabilities | B22: 16232.28 | C22: 15122.68 | D22: 13654.37 | E22: 12284.53 | F22: 10847.13
A23: ASSETS
A24: NON-CURRENT ASSETS
A25: Tangible Assets | B25: 2843.38 | C25: 2606.39 | D25: 2284.67 | E25: 2017.02 | F25: 1862.2
A26: Intangible Assets | B26: 741.22 | C26: 803.49 | D26: 888.73 | E26: 39.73 | F26: 44.71
A27: Capital Work-In-Progress | B27: 166.41 | C27: 209.09 | D27: 175.13 | E27: 167.5 | F27: 147.3
A28: Fixed Assets | B28: 3753.59 | C28: 3642.11 | D28: 3348.53 | E28: 2224.25 | F28: 2054.21
A29: Non-Current Investments | B29: 5380.31 | C29: 5266.09 | D29: 5528.79 | E29: 5365.06 | F29: 3413.62
A30: Deferred Tax Assets [Net] | B30: 2.53 | C30: 6.32 | D30: 2.09 | E30: 0.67 | F30: 17.95
A31: Long Term Loans And Advances | B31: 0 | C31: 0 | D31: 0 | E31: 0 | F31: 22.48
A32: Other Non-Current Assets | B32: 158.3 | C32: 123.42 | D32: 120.75 | E32: 126.56 | F32: 226.92
A33: Total Non-Current Assets | B33: 9699.82 | C33: 9443.06 | D33: 9405.41 | E33: 7967.69 | F33: 6071.19
A34: CURRENT ASSETS
A35: Current Investments | B35: 2087.55 | C35: 1666.6 | D35: 736.47 | E35: 854.56 | F35: 746.01
A36: Inventories | B36: 2300.11 | C36: 1946.97 | D36: 2024.2 | E36: 1911.37 | F36: 1734.28
A37: Trade Receivables | B37: 888.5 | C37: 898.72 | D37: 848.75 | E37: 646.15 | F37: 561.58
A38: Cash And Cash Equivalents | B38: 578.01 | C38: 666.36 | D38: 325.92 | E38: 570.14 | F38: 1329.03
A39: Short Term Loans And Advances | B39: 0 | C39: 0 | D39: 0 | E39: 0 | F39: 14.46
A40: OtherCurrentAssets | B40: 678.29 | C40: 500.97 | D40: 313.62 | E40: 334.62 | F40: 390.58
...

Sheet P&L DABUR IND 
A1: Profit & Loss account of Dabur India (in Rs. Cr.) | B1: 45717 | C1: 45352 | D1: 44986 | E1: 44621 | F1: 44256
A2: INCOME
A3: Revenue From Operations [Gross] | B3: 12400.01 | C3: 12261.65 | D3: 11426.51 | E3: 10808.03 | F3: 9507.81
A4: Less: Excise/Sevice Tax/Other Levies | B4: 0 | C4: 0 | D4: 0 | E4: 0 | F4: 15.05
A5: Revenue From Operations [Net] | B5: 12400.01 | C5: 12261.65 | D5: 11426.51 | E5: 10808.03 | F5: 9492.76
A6: Total Operating Revenues | B6: 12563.09 | C6: 12404.01 | D6: 11529.89 | E6: 10888.68 | F6: 9546.6
A7: Other Income | B7: 550.1 | C7: 482.41 | D7: 445.39 | E7: 393.16 | F7: 325.29
A8: Total Revenue | B8: 13113.19 | C8: 12886.42 | D8: 11975.28 | E8: 11281.84 | F8: 9871.89
A9: EXPENSES
A10: Cost Of Materials Consumed | B10: 5263.68 | C10: 5186.9 | D10: 5306.97 | E10: 4766.12 | F10: 3998.58
A11: Purchase Of Stock-In Trade | B11: 1328.28 | C11: 1211.11 | D11: 1052.49 | E11: 882.12 | F11: 982.53
A12: Operating And Direct Expenses | B12: 0 | C12: 0 | D12: 0 | E12: 0 | F12: 0
A13: Changes In Inventories Of FGWIP And Stock In Trade | B13: -57.1 | C13: 48.95 | D13: -90.79 | E13: -8.55 | F13: -207.2
A14: Employee Benefit Expenses | B14: 1291.23 | C14: 1239.56 | D14: 1137 | E14: 1079.95 | F14: 1033.46
A15: Finance Costs | B15: 163.5 | C15: 124.18 | D15: 78.24 | E15: 38.6 | F15: 30.81
A16: Depreciation And Amortisation Expenses | B16: 445.6 | C16: 399.21 | D16: 310.96 | E16: 252.89 | F16: 240.13
A17: Other Expenses | B17: 2420.66 | C17: 2317.26 | D17: 1960.1 | E17: 1915.23 | F17: 1736.55
A18: Total Expenses | B18: 10855.85 | C18: 10527.17 | D18: 9754.97 | E18: 8926.36 | F18: 7814.86
A19: Profit/Loss Before Exceptional, ExtraOrdinary Items And Tax | B19: 2257.34 | C19: 2359.25 | D19: 2220.31 | E19: 2355.48 | F19: 2057.03
A20: Exceptional Items | B20: 0 | C20: 0 | D20: 0 | E20: -85 | F20: 0
A21: Profit/Loss Before Tax | B21: 2257.34 | C21: 2359.25 | D21: 2220.31 | E21: 2270.48 | F21: 2057.03
A22: Tax Expenses-Continued Operations
A23: Current Tax | B23: 499.06 | C23: 539.53 | D23: 481.63 | E23: 442.17 | F23: 505.18
A24: Less: MAT Credit Entitlement | B24: 0 | C24: 0 | D24: 0 | E24: 0 | F24: 0
A25: Deferred Tax | B25: 18.41 | C25: 7.9 | D25: 35.72 | E25: 84.21 | F25: -144.11
A26: Other Direct Taxes | B26: 0 | C26: 0 | D26: 0 | E26: 0 | F26: 0
A27: Total Tax Expenses | B27: 517.47 | C27: 547.43 | D27: 517.35 | E27: 526.38 | F27: 361.07
A28: Profit/Loss After Tax And Before ExtraOrdinary Items | B28: 1739.87 | C28: 1811.82 | D28: 1702.96 | E28: 1744.1 | F28: 1695.96
A29: Profit/Loss From Continuing Operations | B29: 1739.87 | C29: 1811.82 | D29: 1702.96 | E29: 1744.1 | F29: 1695.96
A30: Profit/Loss For The Period | B30: 1739.87 | C30: 1811.82 | D30: 1702.96 | E30: 1744.1 | F30: 1695.96
A31: Minority Interest | B31: 27.21 | C31: 31.37 | D31: 5.82 | E31: -3.08 | F31: -1.65
A32: Consolidated Profit/Loss After MI And Associates | B32: 1767.63 | C32: 1842.68 | D32: 1707.15 | E32: 1739.22 | F32: 1693.3
A33: OTHER ADDITIONAL INFORMATION
A34: EARNINGS PER SHARE
A35: Basic EPS (Rs.) | B35: 10 | C35: 10 | D35: 10 | E35: 10 | F35: 10
A36: Diluted EPS (Rs.) | B36: 10 | C36: 10 | D36: 10 | E36: 10 | F36: 10
A37: DIVIDEND AND DIVIDEND PERCENTAGE
A38: Equity Share Dividend | B38: 974.78 | C38: 965.76 | D38: 921.31 | E38: 972.32 | F38: 592.09
A39: Tax On Dividend | B39: 0 | C39: 0 | D39: 0 | E39: 0 | F39: 0

Sheet BS BRITANNIA 
A1: Balance Sheet of Britannia Industries (in Rs. Cr.) | B1: 45717 | C1: 45352 | D1: 44986 | E1: 44621 | F1: 44256
A2: EQUITIES AND LIABILITIES
A3: SHAREHOLDER'S FUNDS
A4: Equity Share Capital | B4: 24.09 | C4: 24.09 | D4: 24.09 | E4: 24.09 | F4: 24.09
A5: Total Share Capital | B5: 24.09 | C5: 24.09 | D5: 24.09 | E5: 24.09 | F5: 24.09
A6: Reserves and Surplus | B6: 4331.63 | C6: 3917.43 | D6: 3510.18 | E6: 2534.01 | F6: 3495.47
A7: Total Reserves and Surplus | B7: 4331.63 | C7: 3917.43 | D7: 3510.18 | E7: 2534.01 | F7: 3495.47
A8: Total Shareholders Funds | B8: 4355.72 | C8: 3941.52 | D8: 3534.27 | E8: 2558.1 | F8: 3547.66
A9: Minority Interest | B9: 25.6 | C9: 24.5 | D9: 30.23 | E9: 27.5 | F9: 36.34
A10: NON-CURRENT LIABILITIES
A11: Long Term Borrowings | B11: 712.94 | C11: 904.72 | D11: 1551.8 | E11: 706.99 | F11: 747.75
A12: Deferred Tax Liabilities [Net] | B12: 1.8 | C12: 2.06 | D12: 1.87 | E12: 0.81 | F12: 8.69
A13: Other Long Term Liabilities | B13: 91.66 | C13: 85.79 | D13: 74.51 | E13: 66.4 | F13: 54.07
A14: Long Term Provisions | B14: 32.57 | C14: 30.56 | D14: 25.64 | E14: 0 | F14: 0
A15: Total Non-Current Liabilities | B15: 838.97 | C15: 1023.13 | D15: 1653.82 | E15: 774.2 | F15: 810.51
A16: CURRENT LIABILITIES
A17: Short Term Borrowings | B17: 511.83 | C17: 1136.49 | D17: 1428.71 | E17: 1758.55 | F17: 1339.42
A18: Trade Payables | B18: 1752.23 | C18: 1627.48 | D18: 1448.81 | E18: 1285.22 | F18: 1314.75
A19: Other Current Liabilities | B19: 749.54 | C19: 761.24 | D19: 743.49 | E19: 626.85 | F19: 572.63
A20: Short Term Provisions | B20: 604.66 | C20: 559.2 | D20: 513.39 | E20: 485.11 | F20: 387.47
A21: Total Current Liabilities | B21: 3618.26 | C21: 4084.41 | D21: 4134.4 | E21: 4155.73 | F21: 3614.27
A22: Total Capital And Liabilities | B22: 8838.55 | C22: 9073.56 | D22: 9352.72 | E22: 7515.53 | F22: 8008.78
A23: ASSETS
A24: NON-CURRENT ASSETS
A25: Tangible Assets | B25: 2763.51 | C25: 2630.42 | D25: 2512.82 | E25: 1598 | F25: 1648.51
A26: Intangible Assets | B26: 7.51 | C26: 10.9 | D26: 14.24 | E26: 15.6 | F26: 8.54
A27: Capital Work-In-Progress | B27: 89.2 | C27: 187.54 | D27: 105 | E27: 535.68 | F27: 116.52
A28: Fixed Assets | B28: 2860.22 | C28: 2828.86 | D28: 2632.06 | E28: 2149.28 | F28: 1773.57
A29: Non-Current Investments | B29: 1753.79 | C29: 1070.21 | D29: 1523.25 | E29: 928.64 | F29: 1387.44
A30: Deferred Tax Assets [Net] | B30: 36.59 | C30: 43.88 | D30: 43.64 | E30: 44.93 | F30: 9.66
A31: Long Term Loans And Advances | B31: 0 | C31: 0 | D31: 150 | E31: 100 | F31: 74.58
A32: Other Non-Current Assets | B32: 141.49 | C32: 152.13 | D32: 129.38 | E32: 182.65 | F32: 207.95
A33: Total Non-Current Assets | B33: 4924.87 | C33: 4224.9 | D33: 4606.49 | E33: 3545.11 | F33: 3589.1
A34: CURRENT ASSETS
A35: Current Investments | B35: 1111.64 | C35: 1696.51 | D35: 1800.99 | E35: 833.73 | F35: 1393.25
A36: Inventories | B36: 1236.51 | C36: 1181.22 | D36: 1193.26 | E36: 1367.49 | F36: 1091.49
A37: Trade Receivables | B37: 448.61 | C37: 393.33 | D37: 328.94 | E37: 331.93 | F37: 257.27
A38: Cash And Cash Equivalents | B38: 312.48 | C38: 446.35 | D38: 197.98 | E38: 184.9 | F38: 211.34
A39: Short Term Loans And Advances | B39: 50 | C39: 460 | D39: 560 | E39: 698 | F39: 946.56
A40: OtherCurrentAssets | B40: 754.44 | C40: 671.25 | D40: 665.06 | E40: 554.37 | F40: 519.77
...

Sheet P&L BRITANNIA
A1: Profit & Loss account of Britannia Industries (in Rs. Cr.) | B1: 45717 | C1: 45352 | D1: 44986 | E1: 44621 | F1: 44256
A2: INCOME
A3: Revenue From Operations [Gross] | B3: 17535.02 | C3: 16546.21 | D3: 15984.9 | E3: 13944.67 | F3: 12883.04
A4: Less: Excise/Sevice Tax/Other Levies | B4: 0 | C4: 0 | D4: 0 | E4: 0 | F4: 0
A5: Revenue From Operations [Net] | B5: 17535.02 | C5: 16546.21 | D5: 15984.9 | E5: 13944.67 | F5: 12883.04
A6: Total Operating Revenues | B6: 17942.67 | C6: 16769.27 | D6: 16300.55 | E6: 14136.26 | F6: 13136.14
A7: Other Income | B7: 227.09 | C7: 214.18 | D7: 215.86 | E7: 222.83 | F7: 312.87
A8: Total Revenue | B8: 18169.76 | C8: 16983.45 | D8: 16516.41 | E8: 14359.09 | F8: 13449.01
A9: EXPENSES
A10: Cost Of Materials Consumed | B10: 9859.45 | C10: 8546.89 | D10: 8326.7 | E10: 7473.97 | F10: 6502.33
A11: Purchase Of Stock-In Trade | B11: 809.35 | C11: 941.48 | D11: 1337.13 | E11: 1361.59 | F11: 1160.89
A12: Operating And Direct Expenses | B12: 0 | C12: 0 | D12: 0 | E12: 0 | F12: 0
A13: Changes In Inventories Of FGWIP And Stock In Trade | B13: -64.75 | C13: 3.66 | D13: -72.53 | E13: -75.26 | F13: -37.12
A14: Employee Benefit Expenses | B14: 704.59 | C14: 708.7 | D14: 658.38 | E14: 542.26 | F14: 527.38
A15: Finance Costs | B15: 138.8 | C15: 164 | D15: 169.1 | E15: 144.29 | F15: 110.9
A16: Depreciation And Amortisation Expenses | B16: 313.34 | C16: 300.46 | D16: 225.91 | E16: 200.54 | F16: 197.85
A17: Other Expenses | B17: 3446.88 | C17: 3398.7 | D17: 3219.96 | E17: 2632.19 | F17: 2473.37
A18: Total Expenses | B18: 15207.66 | C18: 14063.89 | D18: 13864.65 | E18: 12279.58 | F18: 10935.6
A19: Profit/Loss Before Exceptional, ExtraOrdinary Items And Tax | B19: 2962.1 | C19: 2919.56 | D19: 2651.76 | E19: 2079.51 | F19: 2513.41
A20: Exceptional Items | B20: -24.79 | C20: -2.9 | D20: 375.6 | E20: -0.98 | F20: -0.61
A21: Profit/Loss Before Tax | B21: 2937.31 | C21: 2916.66 | D21: 3027.36 | E21: 2078.53 | F21: 2512.8
A22: Tax Expenses-Continued Operations
A23: Current Tax | B23: 741.68 | C23: 765.69 | D23: 720.97 | E23: 612.24 | F23: 657.12
A24: Less: MAT Credit Entitlement | B24: 0 | C24: 0 | D24: 0 | E24: 0 | F24: 0
A25: Deferred Tax | B25: 7.03 | C25: 13.56 | D25: -4.52 | E25: -49.89 | F25: 5.9
A26: Other Direct Taxes | B26: 0 | C26: 0 | D26: 0 | E26: 0 | F26: 0
A27: Total Tax Expenses | B27: 748.71 | C27: 779.25 | D27: 716.45 | E27: 562.35 | F27: 663.02
A28: Profit/Loss After Tax And Before ExtraOrdinary Items | B28: 2188.6 | C28: 2137.41 | D28: 2310.91 | E28: 1516.18 | F28: 1849.78
A29: Profit/Loss From Continuing Operations | B29: 2188.6 | C29: 2137.41 | D29: 2310.91 | E29: 1516.18 | F29: 1849.78
A30: Profit/Loss For The Period | B30: 2188.6 | C30: 2137.41 | D30: 2310.91 | E30: 1516.18 | F30: 1849.78
A31: Minority Interest | B31: 0.87 | C31: 5.59 | D31: 5.45 | E31: 8.84 | F31: 13.31
A32: Consolidated Profit/Loss After MI And Associates | B32: 2178.73 | C32: 2139.81 | D32: 2321.77 | E32: 1524.82 | F32: 1863.9
A33: OTHER ADDITIONAL INFORMATION
A34: EARNINGS PER SHARE
A35: Basic EPS (Rs.) | B35: 90 | C35: 89 | D35: 96 | E35: 63 | F35: 77
A36: Diluted EPS (Rs.) | B36: 90 | C36: 89 | D36: 96 | E36: 63 | F36: 77
A37: DIVIDEND AND DIVIDEND PERCENTAGE
A38: Equity Share Dividend | B38: 1770.38 | C38: 1734.25 | D38: 1360.91 | E38: 1794.47 | F38: 2839.66
A39: Tax On Dividend | B39: 0 | C39: 0 | D39: 0 | E39: 0 | F39: 0

Sheet ROE ROA ITC HUL
B1: DuPont Analysis-ITC(Rs. Cr.) | K1: DuPont Analysis-HUL(Rs. Cr.)
A2: INPUT | B2: FORMULA | C2: FY25 | D2: FY24 | E2: FY23 | F2: FY22 | G2: FY21 | J2: INPUT | K2: FORMULA | L2: FY25 | M2: FY24 | N2: FY23 | O2: FY22 | P2: FY21
A3: Net Revenue(Net sales) | C3: ='P&L ITC'!B5 -> 74653.32 | D3: ='P&L ITC'!C5 -> 70315.49 | E3: ='P&L ITC'!D5 -> 70245.22 | F3: ='P&L ITC'!E5 -> 60081.36 | G3: ='P&L ITC'!F5 -> 48952.81 | J3: Net Revenue(Net sales) | L3: ='P&L HUL'!B5 -> 62288 | M3: ='P&L HUL'!C5 -> 60966 | N3: ='P&L HUL'!D5 -> 59549 | O3: ='P&L HUL'!E5 -> 51548 | P3: ='P&L HUL'!F5 -> 46321
A4: Net income (PAT) | C4: ='P&L ITC'!B28 -> 19926.05 | D4: ='P&L ITC'!C28 -> 20723.75 | E4: ='P&L ITC'!D28 -> 19427.68 | F4: ='P&L ITC'!E28 -> 15485.65 | G4: ='P&L ITC'!F28 -> 13389.8 | J4: Net income (PAT) | L4: ='P&L HUL'!B28 -> 10679 | M4: ='P&L HUL'!C28 -> 10286 | N4: ='P&L HUL'!D28 -> 10145 | O4: ='P&L HUL'!E28 -> 8887 | P4: ='P&L HUL'!F28 -> 8000
A5: EBT | C5: ='P&L ITC'!B21 -> 26816.52 | D5: ='P&L ITC'!C21 -> 27112.27 | E5: ='P&L ITC'!D21 -> 25866.08 | F5: ='P&L ITC'!E21 -> 20722.99 | G5: ='P&L ITC'!F21 -> 17945.09 | J5: EBT | L5: ='P&L HUL'!B21 -> 14423 | M5: ='P&L HUL'!C21 -> 13930 | N5: ='P&L HUL'!D21 -> 13346 | O5: ='P&L HUL'!E21 -> 11874 | P5: ='P&L HUL'!F21 -> 10606
A6: EBIT | C6: ='P&L ITC'!B19+'P&L ITC'!B15 -> 26861.58 | D6: ='P&L ITC'!C19+'P&L ITC'!C15 -> 27165.8 | E6: ='P&L ITC'!D19+'P&L ITC'!D15 -> 25836.41 | F6: ='P&L ITC'!E19+'P&L ITC'!E15 -> 20762.35 | G6: ='P&L ITC'!F19+'P&L ITC'!F15 -> 17989.67 | J6: EBIT | L6: ='P&L HUL'!B21+'P&L HUL'!B15 -> 14818 | M6: ='P&L HUL'!C21+'P&L HUL'!C15 -> 14264 | N6: ='P&L HUL'!D21+'P&L HUL'!D15 -> 13460 | O6: ='P&L HUL'!E21+'P&L HUL'!E15 -> 11980 | P6: ='P&L HUL'!F21+'P&L HUL'!F15 -> 10723
A7: Total Assets | C7: ='BS ITC'!B42 -> 88090.68 | D7: ='BS ITC'!C42 -> 91826.16 | E7: ='BS ITC'!D42 -> 85882.98 | F7: ='BS ITC'!E42 -> 77259.55 | G7: ='BS ITC'!F42 -> 73819.3 | J7: Total Assets | L7: ='BS HUL'!B42 -> 78313 | M7: ='BS HUL'!C42 -> 77076 | N7: ='BS HUL'!D42 -> 71825 | O7: ='BS HUL'!E42 -> 69737 | P7: ='BS HUL'!F42 -> 68116
A8: Shareholders equity | C8: ='BS ITC'!B8 -> 70030.05 | D8: ='BS ITC'!C8 -> 74507 | E8: ='BS ITC'!D8 -> 69155.26 | F8: ='BS ITC'!E8 -> 62455.57 | G8: ='BS ITC'!F8 -> 60347.34 | J8: Shareholders equity | L8: ='BS HUL'!B8 -> 49153 | M8: ='BS HUL'!C8 -> 50973 | N8: ='BS HUL'!D8 -> 50221 | O8: ='BS HUL'!E8 -> 48760 | P8: ='BS HUL'!F8 -> 47434
B11: 5 step DuPont Analysis for ROE | K11: 5 step DuPont Analysis for ROE
A12: Tax Burden | B12: Net income/EBT | C12: =C4/C5 -> 0.7430513 | D12: =D4/D5 -> 0.76436794 | E12: =E4/E5 -> 0.75108714 | F12: =F4/F5 -> 0.7472691 | G12: =G4/G5 -> 0.74615396 | J12: Tax Burden | K12: Net income/EBT | L12: =L4/L5 -> 0.74041462 | M12: =M4/M5 -> 0.73840632 | N12: =N4/N5 -> 0.76015285 | O12: =O4/O5 -> 0.74844197 | P12: =P4/P5 -> 0.75429002
A13: Interest Burden | B13: EBT/EBIT | C13: =C5/C6 -> 0.99832251 | D13: =D5/D6 -> 0.99802951 | E13: =E5/E6 -> 1.0011484 | F13: =F5/F6 -> 0.99810426 | G13: =G5/G6 -> 0.99752191 | J13: Interest Burden | K13: EBT/EBIT | L13: =L5/L6 -> 0.97334323 | M13: =M5/M6 -> 0.97658441 | N13: =N5/N6 -> 0.99153046 | O13: =O5/O6 -> 0.99115192 | P13: =P5/P6 -> 0.98908887
A14: Operating Margin | B14: EBIT/Revenue | C14: =C6/C3 -> 0.35981762 | D14: =D6/D3 -> 0.38634162 | E14: =E6/E3 -> 0.3678031 | F14: =F6/F3 -> 0.34557057 | G14: =G6/G3 -> 0.36749004 | J14: Operating Margin | K14: EBIT/Revenue | L14: =L6/L3 -> 0.23789494 | M14: =M6/M3 -> 0.23396647 | N14: =N6/N3 -> 0.22603234 | O14: =O6/O3 -> 0.23240475 | P14: =P6/P3 -> 0.23149328
A15: Asset Turnover | B15: Revenue/Total Asset | C15: =C3/C7 -> 0.84745991 | D15: =D3/D7 -> 0.76574573 | E15: =E3/E7 -> 0.81791782 | F15: =F3/F7 -> 0.7776561 | G15: =G3/G7 -> 0.66314378 | J15: Asset Turnover | K15: Revenue/Total Asset | L15: =L3/L7 -> 0.79537242 | M15: =M3/M7 -> 0.79098552 | N15: =N3/N7 -> 0.82908458 | O15: =O3/O7 -> 0.73917719 | P15: =P3/P7 -> 0.68003112
A16: Equity Multiplier | B16: Total Asset/Equity | C16: =C7/C8 -> 1.2578983 | D16: =D7/D8 -> 1.2324501 | E16: =E7/E8 -> 1.2418864 | F16: =F7/F8 -> 1.2370322 | G16: =G7/G8 -> 1.2232403 | J16: Equity Multiplier | K16: Total Asset/Equity | L16: =L7/L8 -> 1.5932496 | M16: =M7/M8 -> 1.5120946 | N16: =N7/N8 -> 1.4301786 | O16: =O7/O8 -> 1.4302092 | P16: =P7/P8 -> 1.4360164
A17: ROE | B17: Multiplication of above | C17: =C12*C13*C14*C15*C16 -> 0.28453571 | D17: =D12*D13*D14*D15*D16 -> 0.27814501 | E17: =E12*E13*E14*E15*E16 -> 0.28092845 | F17: =F12*F13*F14*F15*F16 -> 0.24794666 | G17: =G12*G13*G14*G15*G16 -> 0.22187888 | J17: ROE | K17: Multiplication of above | L17: =L12*L13*L14*L15*L16 -> 0.21726039 | M17: =M12*M13*M14*M15*M16 -> 0.20179311 | N17: =N12*N13*N14*N15*N16 -> 0.20200713 | O17: =O12*O13*O14*O15*O16 -> 0.18226005 | P17: =P12*P13*P14*P15*P16 -> 0.16865539
B20: ROA using DoPont Decomposition | K20: ROA using DoPont Decomposition
A21: Net Profit Margin | B21: Net Income/Revenue | C21: =C4/C3 -> 0.26691445 | D21: =D4/D3 -> 0.29472524 | E21: =E4/E3 -> 0.27656942 | F21: =F4/F3 -> 0.25774466 | G21: =G4/G3 -> 0.27352465 | J21: Net Profit Margin | K21: Net Income/Revenue | L21: =L4/L3 -> 0.17144554 | M21: =M4/M3 -> 0.16871699 | N21: =N4/N3 -> 0.1703639 | O21: =O4/O3 -> 0.17240242 | P21: =P4/P3 -> 0.17270784
A22: Asset Turnover | B22: Revenue/Total Assets | C22: =C3/C7 -> 0.84745991 | D22: =D3/D7 -> 0.76574573 | E22: =E3/E7 -> 0.81791782 | F22: =F3/F7 -> 0.7776561 | G22: =G3/G7 -> 0.66314378 | J22: Asset Turnover | K22: Revenue/Total Assets | L22: =L3/L7 -> 0.79537242 | M22: =M3/M7 -> 0.79098552 | N22: =N3/N7 -> 0.82908458 | O22: =O3/O7 -> 0.73917719 | P22: =P3/P7 -> 0.68003112
A23: ROA(DuPont) | B23: NPM*Assets Turnover | C23: =C21*C22 -> 0.2261993 | D23: =D21*D22 -> 0.2256846 | E23: =E21*E22 -> 0.22621106 | F23: =F21*F22 -> 0.20043671 | G23: =G21*G22 -> 0.18138617 | J23: ROA(DuPont) | K23: NPM*Assets Turnover | L23: =L21*L22 -> 0.13636306 | M23: =M21*M22 -> 0.1334527 | N23: =N21*N22 -> 0.14124608 | O23: =O21*O22 -> 0.12743594 | P23: =P21*P22 -> 0.11744671

Sheet ROE ROA DABUR BRITANNIA
B1: DuPont Analysis-DABUR IND(Rs. Cr.) | K1: DuPont Analysis-BRITANNAI(Rs. Cr.)
A2: INPUT | B2: FORMULA | C2: FY25 | D2: FY24 | E2: FY23 | F2: FY22 | G2: FY21 | J2: INPUT | K2: FORMULA | L2: FY25 | M2: FY24 | N2: FY23 | O2: FY22 | P2: FY21
A3: Net Revenue(Net sales) | C3: ='P&L DABUR IND '!B5 -> 12400.01 | D3: ='P&L DABUR IND '!C5 -> 12261.65 | E3: ='P&L DABUR IND '!D5 -> 11426.51 | F3: ='P&L DABUR IND '!E5 -> 10808.03 | G3: ='P&L DABUR IND '!F5 -> 9492.76 | J3: Net Revenue(Net sales) | L3: ='P&L BRITANNIA'!B5 -> 17535.02 | M3: ='P&L BRITANNIA'!C5 -> 16546.21 | N3: ='P&L BRITANNIA'!D5 -> 15984.9 | O3: ='P&L BRITANNIA'!E5 -> 13944.67 | P3: ='P&L BRITANNIA'!F5 -> 12883.04
A4: Net income (PAT) | C4: ='P&L DABUR IND '!B28 -> 1739.87 | D4: ='P&L DABUR IND '!C28 -> 1811.82 | E4: ='P&L DABUR IND '!D28 -> 1702.96 | F4: ='P&L DABUR IND '!E28 -> 1744.1 | G4: ='P&L DABUR IND '!F28 -> 1695.96 | J4: Net income (PAT) | L4: ='P&L BRITANNIA'!B28 -> 2188.6 | M4: ='P&L BRITANNIA'!C28 -> 2137.41 | N4: ='P&L BRITANNIA'!D28 -> 2310.91 | O4: ='P&L BRITANNIA'!E28 -> 1516.18 | P4: ='P&L BRITANNIA'!F28 -> 1849.78
A5: EBT | C5: ='P&L DABUR IND '!B21 -> 2257.34 | D5: ='P&L DABUR IND '!C21 -> 2359.25 | E5: ='P&L DABUR IND '!D21 -> 2220.31 | F5: ='P&L DABUR IND '!E21 -> 2270.48 | G5: ='P&L DABUR IND '!F21 -> 2057.03 | J5: EBT | L5: ='P&L BRITANNIA'!B21 -> 2937.31 | M5: ='P&L BRITANNIA'!C21 -> 2916.66 | N5: ='P&L BRITANNIA'!D21 -> 3027.36 | O5: ='P&L BRITANNIA'!E21 -> 2078.53 | P5: ='P&L BRITANNIA'!F21 -> 2512.8
A6: EBIT | C6: ='P&L DABUR IND '!B19+'P&L DABUR IND '!B15 -> 2420.84 | D6: ='P&L DABUR IND '!C19+'P&L DABUR IND '!C15 -> 2483.43 | E6: ='P&L DABUR IND '!D19+'P&L DABUR IND '!D15 -> 2298.55 | F6: ='P&L DABUR IND '!E19+'P&L DABUR IND '!E15 -> 2394.08 | G6: ='P&L DABUR IND '!F19+'P&L DABUR IND '!F15 -> 2087.84 | J6: EBIT | L6: ='P&L BRITANNIA'!B21+'P&L BRITANNIA'!B15 -> 3076.11 | M6: ='P&L BRITANNIA'!C21+'P&L BRITANNIA'!C15 -> 3080.66 | N6: ='P&L BRITANNIA'!D21+'P&L BRITANNIA'!D15 -> 3196.46 | O6: ='P&L BRITANNIA'!E21+'P&L BRITANNIA'!E15 -> 2222.82 | P6: ='P&L BRITANNIA'!F21+'P&L BRITANNIA'!F15 -> 2623.7
A7: Total Assets | C7: ='BS DABUR IND'!B42 -> 16232.28 | D7: ='BS DABUR IND'!C42 -> 15122.68 | E7: ='BS DABUR IND'!D42 -> 13654.37 | F7: ='BS DABUR IND'!E42 -> 12284.53 | G7: ='BS DABUR IND'!F42 -> 10847.13 | J7: Total Assets | L7: ='BS BRITANNIA '!B42 -> 8838.55 | M7: ='BS BRITANNIA '!C42 -> 9073.56 | N7: ='BS BRITANNIA '!D42 -> 9352.72 | O7: ='BS BRITANNIA '!E42 -> 7515.53 | P7: ='BS BRITANNIA '!F42 -> 8008.78
A8: Shareholders equity | C8: ='BS DABUR IND'!B8 -> 10800.69 | D8: ='BS DABUR IND'!C8 -> 9866.3 | E8: ='BS DABUR IND'!D8 -> 8973.26 | F8: ='BS DABUR IND'!E8 -> 8381.3 | G8: ='BS DABUR IND'!F8 -> 7663.53 | J8: Shareholders equity | L8: ='BS BRITANNIA '!B8 -> 4355.72 | M8: ='BS BRITANNIA '!C8 -> 3941.52 | N8: ='BS BRITANNIA '!D8 -> 3534.27 | O8: ='BS BRITANNIA '!E8 -> 2558.1 | P8: ='BS BRITANNIA '!F8 -> 3547.66
B11: 5 step DuPont Analysis for ROE | K11: 5 step DuPont Analysis for ROE
A12: Tax Burden | B12: Net income/EBT | C12: =C4/C5 -> 0.77076116 | D12: =D4/D5 -> 0.7679644 | E12: =E4/E5 -> 0.766992 | F12: =F4/F5 -> 0.76816356 | G12: =G4/G5 -> 0.82447023 | J12: Tax Burden | K12: Net income/EBT | L12: =L4/L5 -> 0.74510351 | M12: =M4/M5 -> 0.73282796 | N12: =N4/N5 -> 0.76334166 | O12: =O4/O5 -> 0.72944822 | P12: =P4/P5 -> 0.73614295
A13: Interest Burden | B13: EBT/EBIT | C13: =C5/C6 -> 0.93246146 | D13: =D5/D6 -> 0.94999658 | E13: =E5/E6 -> 0.96596115 | F13: =F5/F6 -> 0.94837265 | G13: =G5/G6 -> 0.98524312 | J13: Interest Burden | K13: EBT/EBIT | L13: =L5/L6 -> 0.95487808 | M13: =M5/M6 -> 0.94676465 | N13: =N5/N6 -> 0.94709773 | O13: =O5/O6 -> 0.93508696 | P13: =P5/P6 -> 0.95773145
A14: Operating Margin | B14: EBIT/Revenue | C14: =C6/C3 -> 0.19522887 | D14: =D6/D3 -> 0.20253636 | E14: =E6/E3 -> 0.20115941 | F14: =F6/F3 -> 0.22150938 | G14: =G6/G3 -> 0.21994025 | J14: Operating Margin | K14: EBIT/Revenue | L14: =L6/L3 -> 0.17542666 | M14: =M6/M3 -> 0.18618524 | N14: =N6/N3 -> 0.19996747 | O14: =O6/O3 -> 0.15940284 | P14: =P6/P3 -> 0.20365535
A15: Asset Turnover | B15: Revenue/Total Asset | C15: =C3/C7 -> 0.76391055 | D15: =D3/D7 -> 0.81081197 | E15: =E3/E7 -> 0.83683905 | F15: =F3/F7 -> 0.87980818 | G15: =G3/G7 -> 0.87514024 | J15: Asset Turnover | K15: Revenue/Total Asset | L15: =L3/L7 -> 1.983925 | M15: =M3/M7 -> 1.8235632 | N15: =N3/N7 -> 1.7091178 | O15: =O3/O7 -> 1.8554473 | P15: =P3/P7 -> 1.6086145
A16: Equity Multiplier | B16: Total Asset/Equity | C16: =C7/C8 -> 1.5028929 | D16: =D7/D8 -> 1.532761 | E16: =E7/E8 -> 1.5216733 | F16: =F7/F8 -> 1.465707 | G16: =G7/G8 -> 1.4154221 | J16: Equity Multiplier | K16: Total Asset/Equity | L16: =L7/L8 -> 2.0291823 | M16: =M7/M8 -> 2.3020459 | N16: =N7/N8 -> 2.6462947 | O16: =O7/O8 -> 2.9379344 | P16: =P7/P8 -> 2.2574824
A17: ROE | B17: Multiplication of above | C17: =C12*C13*C14*C15*C16 -> 0.16108878 | D17: =D12*D13*D14*D15*D16 -> 0.18363723 | E17: =E12*E13*E14*E15*E16 -> 0.18978164 | F17: =F12*F13*F14*F15*F16 -> 0.20809421 | G17: =G12*G13*G14*G15*G16 -> 0.22130272 | J17: ROE | K17: Multiplication of above | L17: =L12*L13*L14*L15*L16 -> 0.50246572 | M17: =M12*M13*M14*M15*M16 -> 0.54228064 | N17: =N12*N13*N14*N15*N16 -> 0.6538578 | O17: =O12*O13*O14*O15*O16 -> 0.59269771 | P17: =P12*P13*P14*P15*P16 -> 0.52140848
B20: ROA using DoPont Decomposition | K20: ROA using DoPont Decomposition
A21: Net Profit Margin | B21: Net Income/Revenue | C21: =C4/C3 -> 0.14031198 | D21: =D4/D3 -> 0.14776315 | E21: =E4/E3 -> 0.14903588 | F21: =F4/F3 -> 0.16137076 | G21: =G4/G3 -> 0.17865826 | J21: Net Profit Margin | K21: Net Income/Revenue | L21: =L4/L3 -> 0.12481309 | M21: =M4/M3 -> 0.12917822 | N21: =N4/N3 -> 0.14456831 | O21: =O4/O3 -> 0.10872828 | P21: =P4/P3 -> 0.14358257
A22: Asset Turnover | B22: Revenue/Total Assets | C22: =C3/C7 -> 0.76391055 | D22: =D3/D7 -> 0.81081197 | E22: =E3/E7 -> 0.83683905 | F22: =F3/F7 -> 0.87980818 | G22: =G3/G7 -> 0.87514024 | J22: Asset Turnover | K22: Revenue/Total Assets | L22: =L3/L7 -> 1.983925 | M22: =M3/M7 -> 1.8235632 | N22: =N3/N7 -> 1.7091178 | O22: =O3/O7 -> 1.8554473 | P22: =P3/P7 -> 1.6086145
A23: ROA(DuPont) | B23: NPM*Assets Turnover | C23: =C21*C22 -> 0.10718581 | D23: =D21*D22 -> 0.11980813 | E23: =E21*E22 -> 0.12471905 | F23: =F21*F22 -> 0.14197531 | G23: =G21*G22 -> 0.15635103 | J23: ROA(DuPont) | K23: NPM*Assets Turnover | L23: =L21*L22 -> 0.2476198 | M23: =M21*M22 -> 0.23556465 | N23: =N21*N22 -> 0.24708427 | O23: =O21*O22 -> 0.2017396 | P23: =P21*P22 -> 0.23096901

Sheet Comparision
A1: Inter Company Comparision of All 4 Company
C2: ROE
A3: Company Name | B3: 2021 | C3: 2022 | D3: 2023 | E3: 2024 | F3: 2025 | G3: Average of 5 year
A4: ITC | B4: ='ROE ROA ITC HUL'!G17 -> 0.22187888 | C4: ='ROE ROA ITC HUL'!F17 -> 0.24794666 | D4: ='ROE ROA ITC HUL'!E17 -> 0.28092845 | E4: ='ROE ROA ITC HUL'!D17 -> 0.27814501 | F4: ='ROE ROA ITC HUL'!C17 -> 0.28453571 | G4: =AVERAGE(B4:F4) -> 0.26268694
A5: HUL | B5: ='ROE ROA ITC HUL'!P17 -> 0.16865539 | C5: ='ROE ROA ITC HUL'!O17 -> 0.18226005 | D5: ='ROE ROA ITC HUL'!N17 -> 0.20200713 | E5: ='ROE ROA ITC HUL'!M17 -> 0.20179311 | F5: ='ROE ROA ITC HUL'!L17 -> 0.21726039 | G5: =AVERAGE(B5:F5) -> 0.19439521
A6: DABUR | B6: ='ROE ROA DABUR BRITANNIA'!G17 -> 0.22130272 | C6: ='ROE ROA DABUR BRITANNIA'!F17 -> 0.20809421 | D6: ='ROE ROA DABUR BRITANNIA'!E17 -> 0.18978164 | E6: ='ROE ROA DABUR BRITANNIA'!D17 -> 0.18363723 | F6: ='ROE ROA DABUR BRITANNIA'!C17 -> 0.16108878 | G6: =AVERAGE(B6:F6) -> 0.19278092
A7: BRITANNIA | B7: ='ROE ROA DABUR BRITANNIA'!P17 -> 0.52140848 | C7: ='ROE ROA DABUR BRITANNIA'!O17 -> 0.59269771 | D7: ='ROE ROA DABUR BRITANNIA'!N17 -> 0.6538578 | E7: ='ROE ROA DABUR BRITANNIA'!M17 -> 0.54228064 | F7: ='ROE ROA DABUR BRITANNIA'!L17 -> 0.50246572 | G7: =AVERAGE(B7:F7) -> 0.56254207
C9: ROA
A10: Company Name | B10: 2021 | C10: 2022 | D10: 2023 | E10: 2024 | F10: 2025
A11: ITC | B11: ='ROE ROA ITC HUL'!G23 -> 0.18138617 | C11: ='ROE ROA ITC HUL'!F23 -> 0.20043671 | D11: ='ROE ROA ITC HUL'!E23 -> 0.22621106 | E11: ='ROE ROA ITC HUL'!D23 -> 0.2256846 | F11: ='ROE ROA ITC HUL'!C23 -> 0.2261993 | G11: =AVERAGE(B11:F11) -> 0.21198357
A12: HUL | B12: ='ROE ROA ITC HUL'!P23 -> 0.11744671 | C12: ='ROE ROA ITC HUL'!O23 -> 0.12743594 | D12: ='ROE ROA ITC HUL'!N23 -> 0.14124608 | E12: ='ROE ROA ITC HUL'!M23 -> 0.1334527 | F12: ='ROE ROA ITC HUL'!L23 -> 0.13636306 | G12: =AVERAGE(B12:F12) -> 0.1311889
A13: DABUR | B13: ='ROE ROA DABUR BRITANNIA'!G23 -> 0.15635103 | C13: ='ROE ROA DABUR BRITANNIA'!F23 -> 0.14197531 | D13: ='ROE ROA DABUR BRITANNIA'!E23 -> 0.12471905 | E13: ='ROE ROA DABUR BRITANNIA'!D23 -> 0.11980813 | F13: ='ROE ROA DABUR BRITANNIA'!C23 -> 0.10718581 | G13: =AVERAGE(B13:F13) -> 0.13000787
A14: BRITANNIA | B14: ='ROE ROA DABUR BRITANNIA'!P23 -> 0.23096901 | C14: ='ROE ROA DABUR BRITANNIA'!O23 -> 0.2017396 | D14: ='ROE ROA DABUR BRITANNIA'!N23 -> 0.24708427 | E14: ='ROE ROA DABUR BRITANNIA'!M23 -> 0.23556465 | F14: ='ROE ROA DABUR BRITANNIA'!L23 -> 0.2476198 | G14: =AVERAGE(B14:F14) -> 0.23259547
A16: Intra Company Comparision of ITC
C17: ROE
B18: 2021 | C18: 2022 | D18: 2023 | E18: 2024 | F18: 2025
A19: ='ROE ROA ITC HUL'!A12 -> Tax Burden | B19: ='ROE ROA ITC HUL'!G12 -> 0.74615396 | C19: ='ROE ROA ITC HUL'!F12 -> 0.7472691 | D19: ='ROE ROA ITC HUL'!E12 -> 0.75108714 | E19: ='ROE ROA ITC HUL'!D12 -> 0.76436794 | F19: ='ROE ROA ITC HUL'!C12 -> 0.7430513 | G19: =AVERAGE(B19:F19) -> 0.75038589
A20: ='ROE ROA ITC HUL'!A13 -> Interest Burden | B20: ='ROE ROA ITC HUL'!G13 -> 0.99752191 | C20: ='ROE ROA ITC HUL'!F13 -> 0.99810426 | D20: ='ROE ROA ITC HUL'!E13 -> 1.0011484 | E20: ='ROE ROA ITC HUL'!D13 -> 0.99802951 | F20: ='ROE ROA ITC HUL'!C13 -> 0.99832251 | G20: =AVERAGE(B20:F20) -> 0.99862531
A21: ='ROE ROA ITC HUL'!A14 -> Operating Margin | B21: ='ROE ROA ITC HUL'!G14 -> 0.36749004 | C21: ='ROE ROA ITC HUL'!F14 -> 0.34557057 | D21: ='ROE ROA ITC HUL'!E14 -> 0.3678031 | E21: ='ROE ROA ITC HUL'!D14 -> 0.38634162 | F21: ='ROE ROA ITC HUL'!C14 -> 0.35981762 | G21: =AVERAGE(B21:F21) -> 0.36540459
A22: ='ROE ROA ITC HUL'!A15 -> Asset Turnover | B22: ='ROE ROA ITC HUL'!G15 -> 0.66314378 | C22: ='ROE ROA ITC HUL'!F15 -> 0.7776561 | D22: ='ROE ROA ITC HUL'!E15 -> 0.81791782 | E22: ='ROE ROA ITC HUL'!D15 -> 0.76574573 | F22: ='ROE ROA ITC HUL'!C15 -> 0.84745991 | G22: =AVERAGE(B22:F22) -> 0.77438467
A23: ='ROE ROA ITC HUL'!A16 -> Equity Multiplier | B23: ='ROE ROA ITC HUL'!G16 -> 1.2232403 | C23: ='ROE ROA ITC HUL'!F16 -> 1.2370322 | D23: ='ROE ROA ITC HUL'!E16 -> 1.2418864 | E23: ='ROE ROA ITC HUL'!D16 -> 1.2324501 | F23: ='ROE ROA ITC HUL'!C16 -> 1.2578983 | G23: =AVERAGE(B23:F23) -> 1.2385015
A24: ='ROE ROA ITC HUL'!A17 -> ROE | B24: ='ROE ROA ITC HUL'!G17 -> 0.22187888 | C24: ='ROE ROA ITC HUL'!F17 -> 0.24794666 | D24: ='ROE ROA ITC HUL'!E17 -> 0.28092845 | E24: ='ROE ROA ITC HUL'!D17 -> 0.27814501 | F24: ='ROE ROA ITC HUL'!C17 -> 0.28453571 | G24: =AVERAGE(B24:F24) -> 0.26268694
D26: ROA
B27: 2021 | C27: 2022 | D27: 2023 | E27: 2024 | F27: 2025
A28: ='ROE ROA ITC HUL'!A21 -> Net Profit Margin | B28: ='ROE ROA ITC HUL'!G21 -> 0.27352465 | C28: ='ROE ROA ITC HUL'!F21 -> 0.25774466 | D28: ='ROE ROA ITC HUL'!E21 -> 0.27656942 | E28: ='ROE ROA ITC HUL'!D21 -> 0.29472524 | F28: ='ROE ROA ITC HUL'!C21 -> 0.26691445 | G28: =AVERAGE(B28:F28) -> 0.27389569
A29: ='ROE ROA ITC HUL'!A22 -> Asset Turnover | B29: ='ROE ROA ITC HUL'!G22 -> 0.66314378 | C29: ='ROE ROA ITC HUL'!F22 -> 0.7776561 | D29: ='ROE ROA ITC HUL'!E22 -> 0.81791782 | E29: ='ROE ROA ITC HUL'!D22 -> 0.76574573 | F29: ='ROE ROA ITC HUL'!C22 -> 0.84745991 | G29: =AVERAGE(B29:F29) -> 0.77438467
A30: ='ROE ROA ITC HUL'!A23 -> ROA(DuPont) | B30: ='ROE ROA ITC HUL'!G23 -> 0.18138617 | C30: ='ROE ROA ITC HUL'!F23 -> 0.20043671 | D30: ='ROE ROA ITC HUL'!E23 -> 0.22621106 | E30: ='ROE ROA ITC HUL'!D23 -> 0.2256846 | F30: ='ROE ROA ITC HUL'!C23 -> 0.2261993 | G30: =AVERAGE(B30:F30) -> 0.21198357

Sheet Interpretation
